2014-06-25 16:11:33,383|loggername|INFO |'Traceback (most recent call last):\n  File "/home/awwicker/IdeaProjects/source_code/python/intelanalytics/core/frame.py", line 613, in inspect\n    return self._backend.inspect(self, n, offset)\n  File "/home/awwicker/IdeaProjects/source_code/python/intelanalytics/rest/frame.py", line 243, in inspect\n    rows = self.take(frame, n, offset)\n  File "/home/awwicker/IdeaProjects/source_code/python/intelanalytics/rest/frame.py", line 305, in take\n    r = self.rest_http.get(\'dataframes/{0}/data?offset={2}&count={1}\'.format(frame._id,n, offset))\n  File "/home/awwicker/IdeaProjects/source_code/python/intelanalytics/rest/connection.py", line 130, in get\n    return self.get_full_uri(uri)\n  File "/home/awwicker/IdeaProjects/source_code/python/intelanalytics/rest/connection.py", line 138, in get_full_uri\n    self._check_response(r)\n  File "/home/awwicker/IdeaProjects/source_code/python/intelanalytics/rest/connection.py", line 111, in _check_response\n    response.raise_for_status()\n  File "/usr/local/lib/python2.7/site-packages/requests/models.py", line 795, in raise_for_status\n    raise HTTPError(http_error_msg, response=self)\nHTTPError: 406 Client Error: Not Acceptable\n'
